[2023-12-20T15:20:32.055+0000] {taskinstance.py:1159} INFO - Dependencies all met for dep_context=non-requeueable deps ti=<TaskInstance: crimes_dag.create_cluster manual__2023-12-20T11:55:08.736573+00:00 [queued]>
[2023-12-20T15:20:32.072+0000] {taskinstance.py:1159} INFO - Dependencies all met for dep_context=requeueable deps ti=<TaskInstance: crimes_dag.create_cluster manual__2023-12-20T11:55:08.736573+00:00 [queued]>
[2023-12-20T15:20:32.074+0000] {taskinstance.py:1361} INFO - Starting attempt 5 of 5
[2023-12-20T15:20:32.116+0000] {taskinstance.py:1382} INFO - Executing <Task(DataprocCreateClusterOperator): create_cluster> on 2023-12-20 11:55:08.736573+00:00
[2023-12-20T15:20:32.129+0000] {standard_task_runner.py:57} INFO - Started process 4054 to run task
[2023-12-20T15:20:32.135+0000] {standard_task_runner.py:84} INFO - Running: ['***', 'tasks', 'run', 'crimes_dag', 'create_cluster', 'manual__2023-12-20T11:55:08.736573+00:00', '--job-id', '38', '--raw', '--subdir', 'DAGS_FOLDER/crime_dag.py', '--cfg-path', '/tmp/tmpmpoqpddy']
[2023-12-20T15:20:32.141+0000] {standard_task_runner.py:85} INFO - Job 38: Subtask create_cluster
[2023-12-20T15:20:32.218+0000] {task_command.py:416} INFO - Running <TaskInstance: crimes_dag.create_cluster manual__2023-12-20T11:55:08.736573+00:00 [running]> on host d2fdd2505514
[2023-12-20T15:20:32.334+0000] {taskinstance.py:1662} INFO - Exporting env vars: AIRFLOW_CTX_DAG_OWNER='***' AIRFLOW_CTX_DAG_ID='crimes_dag' AIRFLOW_CTX_TASK_ID='create_cluster' AIRFLOW_CTX_EXECUTION_DATE='2023-12-20T11:55:08.736573+00:00' AIRFLOW_CTX_TRY_NUMBER='5' AIRFLOW_CTX_DAG_RUN_ID='manual__2023-12-20T11:55:08.736573+00:00'
[2023-12-20T15:20:32.336+0000] {dataproc.py:637} INFO - Creating cluster: crimes-cluster
[2023-12-20T15:20:32.351+0000] {connection.py:232} WARNING - Connection schemes (type: google_cloud_platform) shall not contain '_' according to RFC3986.
[2023-12-20T15:20:32.360+0000] {base.py:73} INFO - Using connection ID 'google_cloud_default' for task execution.
[2023-12-20T15:20:38.013+0000] {taskinstance.py:1937} ERROR - Task failed with exception
Traceback (most recent call last):
  File "/home/airflow/.local/lib/python3.8/site-packages/google/api_core/grpc_helpers.py", line 75, in error_remapped_callable
    return callable_(*args, **kwargs)
  File "/home/airflow/.local/lib/python3.8/site-packages/grpc/_channel.py", line 1161, in __call__
    return _end_unary_response_blocking(state, call, False, None)
  File "/home/airflow/.local/lib/python3.8/site-packages/grpc/_channel.py", line 1004, in _end_unary_response_blocking
    raise _InactiveRpcError(state)  # pytype: disable=not-instantiable
grpc._channel._InactiveRpcError: <_InactiveRpcError of RPC that terminated with:
	status = StatusCode.INVALID_ARGUMENT
	details = "Insufficient 'DISKS_TOTAL_GB' quota. Requested 3000.0, available 1096.0."
	debug_error_string = "UNKNOWN:Error received from peer ipv4:142.251.42.106:443 {grpc_message:"Insufficient \'DISKS_TOTAL_GB\' quota. Requested 3000.0, available 1096.0.", grpc_status:3, created_time:"2023-12-20T15:20:38.011917486+00:00"}"
>

The above exception was the direct cause of the following exception:

Traceback (most recent call last):
  File "/home/airflow/.local/lib/python3.8/site-packages/airflow/providers/google/cloud/operators/dataproc.py", line 651, in execute
    operation = self._create_cluster(hook)
  File "/home/airflow/.local/lib/python3.8/site-packages/airflow/providers/google/cloud/operators/dataproc.py", line 567, in _create_cluster
    return hook.create_cluster(
  File "/home/airflow/.local/lib/python3.8/site-packages/airflow/providers/google/common/hooks/base_google.py", line 475, in inner_wrapper
    return func(self, *args, **kwargs)
  File "/home/airflow/.local/lib/python3.8/site-packages/airflow/providers/google/cloud/hooks/dataproc.py", line 324, in create_cluster
    result = client.create_cluster(
  File "/home/airflow/.local/lib/python3.8/site-packages/google/cloud/dataproc_v1/services/cluster_controller/client.py", line 632, in create_cluster
    response = rpc(
  File "/home/airflow/.local/lib/python3.8/site-packages/google/api_core/gapic_v1/method.py", line 131, in __call__
    return wrapped_func(*args, **kwargs)
  File "/home/airflow/.local/lib/python3.8/site-packages/google/api_core/retry.py", line 366, in retry_wrapped_func
    return retry_target(
  File "/home/airflow/.local/lib/python3.8/site-packages/google/api_core/retry.py", line 204, in retry_target
    return target()
  File "/home/airflow/.local/lib/python3.8/site-packages/google/api_core/timeout.py", line 120, in func_with_timeout
    return func(*args, **kwargs)
  File "/home/airflow/.local/lib/python3.8/site-packages/google/api_core/grpc_helpers.py", line 77, in error_remapped_callable
    raise exceptions.from_grpc_error(exc) from exc
google.api_core.exceptions.InvalidArgument: 400 Insufficient 'DISKS_TOTAL_GB' quota. Requested 3000.0, available 1096.0.
[2023-12-20T15:20:38.053+0000] {taskinstance.py:1400} INFO - Marking task as FAILED. dag_id=crimes_dag, task_id=create_cluster, execution_date=20231220T115508, start_date=20231220T152032, end_date=20231220T152038
[2023-12-20T15:20:38.077+0000] {standard_task_runner.py:104} ERROR - Failed to execute job 38 for task create_cluster (400 Insufficient 'DISKS_TOTAL_GB' quota. Requested 3000.0, available 1096.0.; 4054)
[2023-12-20T15:20:38.124+0000] {local_task_job_runner.py:228} INFO - Task exited with return code 1
[2023-12-20T15:20:38.156+0000] {taskinstance.py:2778} INFO - 0 downstream tasks scheduled from follow-on schedule check
