[2023-12-20T14:36:27.104+0000] {taskinstance.py:1159} INFO - Dependencies all met for dep_context=non-requeueable deps ti=<TaskInstance: crimes_dag.create_cluster scheduled__2023-12-10T00:00:00+00:00 [queued]>
[2023-12-20T14:36:27.114+0000] {taskinstance.py:1159} INFO - Dependencies all met for dep_context=requeueable deps ti=<TaskInstance: crimes_dag.create_cluster scheduled__2023-12-10T00:00:00+00:00 [queued]>
[2023-12-20T14:36:27.115+0000] {taskinstance.py:1361} INFO - Starting attempt 2 of 2
[2023-12-20T14:36:27.132+0000] {taskinstance.py:1382} INFO - Executing <Task(DataprocCreateClusterOperator): create_cluster> on 2023-12-10 00:00:00+00:00
[2023-12-20T14:36:27.140+0000] {standard_task_runner.py:57} INFO - Started process 2640 to run task
[2023-12-20T14:36:27.145+0000] {standard_task_runner.py:84} INFO - Running: ['***', 'tasks', 'run', 'crimes_dag', 'create_cluster', 'scheduled__2023-12-10T00:00:00+00:00', '--job-id', '14', '--raw', '--subdir', 'DAGS_FOLDER/crime_dag.py', '--cfg-path', '/tmp/tmprq3252iw']
[2023-12-20T14:36:27.150+0000] {standard_task_runner.py:85} INFO - Job 14: Subtask create_cluster
[2023-12-20T14:36:27.211+0000] {task_command.py:416} INFO - Running <TaskInstance: crimes_dag.create_cluster scheduled__2023-12-10T00:00:00+00:00 [running]> on host d2fdd2505514
[2023-12-20T14:36:27.298+0000] {taskinstance.py:1662} INFO - Exporting env vars: AIRFLOW_CTX_DAG_OWNER='***' AIRFLOW_CTX_DAG_ID='crimes_dag' AIRFLOW_CTX_TASK_ID='create_cluster' AIRFLOW_CTX_EXECUTION_DATE='2023-12-10T00:00:00+00:00' AIRFLOW_CTX_TRY_NUMBER='2' AIRFLOW_CTX_DAG_RUN_ID='scheduled__2023-12-10T00:00:00+00:00'
[2023-12-20T14:36:27.300+0000] {dataproc.py:637} INFO - Creating cluster: crimes-cluster
[2023-12-20T14:36:27.309+0000] {connection.py:232} WARNING - Connection schemes (type: google_cloud_platform) shall not contain '_' according to RFC3986.
[2023-12-20T14:36:27.314+0000] {base.py:73} INFO - Using connection ID 'google_cloud_default' for task execution.
[2023-12-20T14:36:30.694+0000] {taskinstance.py:1937} ERROR - Task failed with exception
Traceback (most recent call last):
  File "/home/airflow/.local/lib/python3.8/site-packages/google/api_core/grpc_helpers.py", line 75, in error_remapped_callable
    return callable_(*args, **kwargs)
  File "/home/airflow/.local/lib/python3.8/site-packages/grpc/_channel.py", line 1161, in __call__
    return _end_unary_response_blocking(state, call, False, None)
  File "/home/airflow/.local/lib/python3.8/site-packages/grpc/_channel.py", line 1004, in _end_unary_response_blocking
    raise _InactiveRpcError(state)  # pytype: disable=not-instantiable
grpc._channel._InactiveRpcError: <_InactiveRpcError of RPC that terminated with:
	status = StatusCode.INVALID_ARGUMENT
	details = "Insufficient 'DISKS_TOTAL_GB' quota. Requested 3000.0, available 1096.0."
	debug_error_string = "UNKNOWN:Error received from peer ipv4:172.217.160.170:443 {created_time:"2023-12-20T14:36:30.693579506+00:00", grpc_status:3, grpc_message:"Insufficient \'DISKS_TOTAL_GB\' quota. Requested 3000.0, available 1096.0."}"
>

The above exception was the direct cause of the following exception:

Traceback (most recent call last):
  File "/home/airflow/.local/lib/python3.8/site-packages/airflow/providers/google/cloud/operators/dataproc.py", line 651, in execute
    operation = self._create_cluster(hook)
  File "/home/airflow/.local/lib/python3.8/site-packages/airflow/providers/google/cloud/operators/dataproc.py", line 567, in _create_cluster
    return hook.create_cluster(
  File "/home/airflow/.local/lib/python3.8/site-packages/airflow/providers/google/common/hooks/base_google.py", line 475, in inner_wrapper
    return func(self, *args, **kwargs)
  File "/home/airflow/.local/lib/python3.8/site-packages/airflow/providers/google/cloud/hooks/dataproc.py", line 324, in create_cluster
    result = client.create_cluster(
  File "/home/airflow/.local/lib/python3.8/site-packages/google/cloud/dataproc_v1/services/cluster_controller/client.py", line 632, in create_cluster
    response = rpc(
  File "/home/airflow/.local/lib/python3.8/site-packages/google/api_core/gapic_v1/method.py", line 131, in __call__
    return wrapped_func(*args, **kwargs)
  File "/home/airflow/.local/lib/python3.8/site-packages/google/api_core/retry.py", line 366, in retry_wrapped_func
    return retry_target(
  File "/home/airflow/.local/lib/python3.8/site-packages/google/api_core/retry.py", line 204, in retry_target
    return target()
  File "/home/airflow/.local/lib/python3.8/site-packages/google/api_core/timeout.py", line 120, in func_with_timeout
    return func(*args, **kwargs)
  File "/home/airflow/.local/lib/python3.8/site-packages/google/api_core/grpc_helpers.py", line 77, in error_remapped_callable
    raise exceptions.from_grpc_error(exc) from exc
google.api_core.exceptions.InvalidArgument: 400 Insufficient 'DISKS_TOTAL_GB' quota. Requested 3000.0, available 1096.0.
[2023-12-20T14:36:30.770+0000] {taskinstance.py:1400} INFO - Marking task as FAILED. dag_id=crimes_dag, task_id=create_cluster, execution_date=20231210T000000, start_date=20231220T143627, end_date=20231220T143630
[2023-12-20T14:36:30.789+0000] {standard_task_runner.py:104} ERROR - Failed to execute job 14 for task create_cluster (400 Insufficient 'DISKS_TOTAL_GB' quota. Requested 3000.0, available 1096.0.; 2640)
[2023-12-20T14:36:30.812+0000] {local_task_job_runner.py:228} INFO - Task exited with return code 1
[2023-12-20T14:36:30.866+0000] {taskinstance.py:2778} INFO - 0 downstream tasks scheduled from follow-on schedule check
