[2023-12-20T19:09:01.222+0000] {taskinstance.py:1159} INFO - Dependencies all met for dep_context=non-requeueable deps ti=<TaskInstance: crimes_dag.load scheduled__2023-12-03T00:00:00+00:00 [queued]>
[2023-12-20T19:09:01.242+0000] {taskinstance.py:1159} INFO - Dependencies all met for dep_context=requeueable deps ti=<TaskInstance: crimes_dag.load scheduled__2023-12-03T00:00:00+00:00 [queued]>
[2023-12-20T19:09:01.244+0000] {taskinstance.py:1361} INFO - Starting attempt 13 of 13
[2023-12-20T19:09:01.280+0000] {taskinstance.py:1382} INFO - Executing <Task(PythonOperator): load> on 2023-12-03 00:00:00+00:00
[2023-12-20T19:09:01.359+0000] {standard_task_runner.py:57} INFO - Started process 7369 to run task
[2023-12-20T19:09:01.365+0000] {standard_task_runner.py:84} INFO - Running: ['***', 'tasks', 'run', 'crimes_dag', 'load', 'scheduled__2023-12-03T00:00:00+00:00', '--job-id', '67', '--raw', '--subdir', 'DAGS_FOLDER/crime_dag.py', '--cfg-path', '/tmp/tmpn_bcb1n9']
[2023-12-20T19:09:01.371+0000] {standard_task_runner.py:85} INFO - Job 67: Subtask load
[2023-12-20T19:09:01.481+0000] {task_command.py:416} INFO - Running <TaskInstance: crimes_dag.load scheduled__2023-12-03T00:00:00+00:00 [running]> on host d2fdd2505514
[2023-12-20T19:09:01.597+0000] {taskinstance.py:1662} INFO - Exporting env vars: AIRFLOW_CTX_DAG_OWNER='***' AIRFLOW_CTX_DAG_ID='crimes_dag' AIRFLOW_CTX_TASK_ID='load' AIRFLOW_CTX_EXECUTION_DATE='2023-12-03T00:00:00+00:00' AIRFLOW_CTX_TRY_NUMBER='13' AIRFLOW_CTX_DAG_RUN_ID='scheduled__2023-12-03T00:00:00+00:00'
[2023-12-20T19:09:08.879+0000] {taskinstance.py:1937} ERROR - Task failed with exception
Traceback (most recent call last):
  File "/opt/airflow/dags/etl_scripts/load.py", line 23, in load_table
    client.get_table(table_id)
  File "/home/airflow/.local/lib/python3.8/site-packages/google/cloud/bigquery/client.py", line 1060, in get_table
    api_response = self._call_api(
  File "/home/airflow/.local/lib/python3.8/site-packages/google/cloud/bigquery/client.py", line 808, in _call_api
    return call()
  File "/home/airflow/.local/lib/python3.8/site-packages/google/api_core/retry.py", line 366, in retry_wrapped_func
    return retry_target(
  File "/home/airflow/.local/lib/python3.8/site-packages/google/api_core/retry.py", line 204, in retry_target
    return target()
  File "/home/airflow/.local/lib/python3.8/site-packages/google/cloud/_http/__init__.py", line 494, in api_request
    raise exceptions.from_http_response(response)
google.api_core.exceptions.NotFound: 404 GET https://bigquery.googleapis.com/bigquery/v2/projects/oceanic-hangout-406022/datasets/crime_dataset/tables/crime_table?prettyPrint=false: Not found: Table oceanic-hangout-406022:crime_dataset.crime_table

During handling of the above exception, another exception occurred:

Traceback (most recent call last):
  File "/home/airflow/.local/lib/python3.8/site-packages/airflow/operators/python.py", line 192, in execute
    return_value = self.execute_callable()
  File "/home/airflow/.local/lib/python3.8/site-packages/airflow/operators/python.py", line 209, in execute_callable
    return self.python_callable(*self.op_args, **self.op_kwargs)
  File "/opt/airflow/dags/etl_scripts/load.py", line 45, in load_table
    load_job.result()
  File "/home/airflow/.local/lib/python3.8/site-packages/google/cloud/bigquery/job/base.py", line 922, in result
    return super(_AsyncJob, self).result(timeout=timeout, **kwargs)
  File "/home/airflow/.local/lib/python3.8/site-packages/google/api_core/future/polling.py", line 261, in result
    raise self._exception
google.api_core.exceptions.BadRequest: 400 Error while reading data, error message: CSV processing encountered too many errors, giving up. Rows: 114604; errors: 1; max bad: 0; error percent: 0
[2023-12-20T19:09:08.930+0000] {taskinstance.py:1400} INFO - Marking task as FAILED. dag_id=crimes_dag, task_id=load, execution_date=20231203T000000, start_date=20231220T190901, end_date=20231220T190908
[2023-12-20T19:09:08.947+0000] {standard_task_runner.py:104} ERROR - Failed to execute job 67 for task load (400 Error while reading data, error message: CSV processing encountered too many errors, giving up. Rows: 114604; errors: 1; max bad: 0; error percent: 0; 7369)
[2023-12-20T19:09:08.976+0000] {local_task_job_runner.py:228} INFO - Task exited with return code 1
[2023-12-20T19:09:08.994+0000] {taskinstance.py:2778} INFO - 0 downstream tasks scheduled from follow-on schedule check
