[2023-12-20T18:14:19.411+0000] {taskinstance.py:1159} INFO - Dependencies all met for dep_context=non-requeueable deps ti=<TaskInstance: crimes_dag.load scheduled__2023-12-03T00:00:00+00:00 [queued]>
[2023-12-20T18:14:19.430+0000] {taskinstance.py:1159} INFO - Dependencies all met for dep_context=requeueable deps ti=<TaskInstance: crimes_dag.load scheduled__2023-12-03T00:00:00+00:00 [queued]>
[2023-12-20T18:14:19.430+0000] {taskinstance.py:1361} INFO - Starting attempt 2 of 2
[2023-12-20T18:14:19.455+0000] {taskinstance.py:1382} INFO - Executing <Task(PythonOperator): load> on 2023-12-03 00:00:00+00:00
[2023-12-20T18:14:19.466+0000] {standard_task_runner.py:57} INFO - Started process 6568 to run task
[2023-12-20T18:14:19.472+0000] {standard_task_runner.py:84} INFO - Running: ['***', 'tasks', 'run', 'crimes_dag', 'load', 'scheduled__2023-12-03T00:00:00+00:00', '--job-id', '56', '--raw', '--subdir', 'DAGS_FOLDER/crime_dag.py', '--cfg-path', '/tmp/tmp7pmf422w']
[2023-12-20T18:14:19.477+0000] {standard_task_runner.py:85} INFO - Job 56: Subtask load
[2023-12-20T18:14:19.539+0000] {task_command.py:416} INFO - Running <TaskInstance: crimes_dag.load scheduled__2023-12-03T00:00:00+00:00 [running]> on host d2fdd2505514
[2023-12-20T18:14:19.632+0000] {taskinstance.py:1662} INFO - Exporting env vars: AIRFLOW_CTX_DAG_OWNER='***' AIRFLOW_CTX_DAG_ID='crimes_dag' AIRFLOW_CTX_TASK_ID='load' AIRFLOW_CTX_EXECUTION_DATE='2023-12-03T00:00:00+00:00' AIRFLOW_CTX_TRY_NUMBER='2' AIRFLOW_CTX_DAG_RUN_ID='scheduled__2023-12-03T00:00:00+00:00'
[2023-12-20T18:14:20.964+0000] {taskinstance.py:1937} ERROR - Task failed with exception
Traceback (most recent call last):
  File "/home/airflow/.local/lib/python3.8/site-packages/airflow/operators/python.py", line 192, in execute
    return_value = self.execute_callable()
  File "/home/airflow/.local/lib/python3.8/site-packages/airflow/operators/python.py", line 209, in execute_callable
    return self.python_callable(*self.op_args, **self.op_kwargs)
  File "/opt/airflow/dags/etl_scripts/load.py", line 18, in load_table
    if blob.exists() == False:
  File "/home/airflow/.local/lib/python3.8/site-packages/google/cloud/storage/blob.py", line 700, in exists
    client._get_resource(
  File "/home/airflow/.local/lib/python3.8/site-packages/google/cloud/storage/client.py", line 387, in _get_resource
    return self._connection.api_request(
  File "/home/airflow/.local/lib/python3.8/site-packages/google/cloud/storage/_http.py", line 72, in api_request
    return call()
  File "/home/airflow/.local/lib/python3.8/site-packages/google/api_core/retry.py", line 366, in retry_wrapped_func
    return retry_target(
  File "/home/airflow/.local/lib/python3.8/site-packages/google/api_core/retry.py", line 204, in retry_target
    return target()
  File "/home/airflow/.local/lib/python3.8/site-packages/google/cloud/_http/__init__.py", line 494, in api_request
    raise exceptions.from_http_response(response)
google.api_core.exceptions.Forbidden: 403 GET https://storage.googleapis.com/storage/v1/b/chicago_crime_bucket/o/transformed%2F2023-12-03_crimes.csv?fields=name&prettyPrint=false: The billing account for the owning project is disabled in state absent
[2023-12-20T18:14:20.992+0000] {taskinstance.py:1400} INFO - Marking task as FAILED. dag_id=crimes_dag, task_id=load, execution_date=20231203T000000, start_date=20231220T181419, end_date=20231220T181420
[2023-12-20T18:14:21.009+0000] {standard_task_runner.py:104} ERROR - Failed to execute job 56 for task load (403 GET https://storage.googleapis.com/storage/v1/b/chicago_crime_bucket/o/transformed%2F2023-12-03_crimes.csv?fields=name&prettyPrint=false: The billing account for the owning project is disabled in state absent; 6568)
[2023-12-20T18:14:21.060+0000] {local_task_job_runner.py:228} INFO - Task exited with return code 1
[2023-12-20T18:14:21.082+0000] {taskinstance.py:2778} INFO - 0 downstream tasks scheduled from follow-on schedule check
