[2023-12-20T14:33:59.265+0000] {taskinstance.py:1159} INFO - Dependencies all met for dep_context=non-requeueable deps ti=<TaskInstance: crimes_dag.submit_pyspark_job scheduled__2023-12-03T00:00:00+00:00 [queued]>
[2023-12-20T14:33:59.279+0000] {taskinstance.py:1159} INFO - Dependencies all met for dep_context=requeueable deps ti=<TaskInstance: crimes_dag.submit_pyspark_job scheduled__2023-12-03T00:00:00+00:00 [queued]>
[2023-12-20T14:33:59.280+0000] {taskinstance.py:1361} INFO - Starting attempt 1 of 1
[2023-12-20T14:33:59.306+0000] {taskinstance.py:1382} INFO - Executing <Task(DataprocSubmitJobOperator): submit_pyspark_job> on 2023-12-03 00:00:00+00:00
[2023-12-20T14:33:59.316+0000] {standard_task_runner.py:57} INFO - Started process 2550 to run task
[2023-12-20T14:33:59.326+0000] {standard_task_runner.py:84} INFO - Running: ['***', 'tasks', 'run', 'crimes_dag', 'submit_pyspark_job', 'scheduled__2023-12-03T00:00:00+00:00', '--job-id', '8', '--raw', '--subdir', 'DAGS_FOLDER/crime_dag.py', '--cfg-path', '/tmp/tmp7ej9m30x']
[2023-12-20T14:33:59.340+0000] {standard_task_runner.py:85} INFO - Job 8: Subtask submit_pyspark_job
[2023-12-20T14:33:59.564+0000] {task_command.py:416} INFO - Running <TaskInstance: crimes_dag.submit_pyspark_job scheduled__2023-12-03T00:00:00+00:00 [running]> on host d2fdd2505514
[2023-12-20T14:33:59.816+0000] {taskinstance.py:1662} INFO - Exporting env vars: AIRFLOW_CTX_DAG_OWNER='***' AIRFLOW_CTX_DAG_ID='crimes_dag' AIRFLOW_CTX_TASK_ID='submit_pyspark_job' AIRFLOW_CTX_EXECUTION_DATE='2023-12-03T00:00:00+00:00' AIRFLOW_CTX_TRY_NUMBER='1' AIRFLOW_CTX_DAG_RUN_ID='scheduled__2023-12-03T00:00:00+00:00'
[2023-12-20T14:33:59.818+0000] {dataproc.py:2123} INFO - Submitting job
[2023-12-20T14:33:59.836+0000] {connection.py:232} WARNING - Connection schemes (type: google_cloud_platform) shall not contain '_' according to RFC3986.
[2023-12-20T14:33:59.841+0000] {base.py:73} INFO - Using connection ID 'google_cloud_default' for task execution.
[2023-12-20T14:34:01.945+0000] {taskinstance.py:1937} ERROR - Task failed with exception
Traceback (most recent call last):
  File "/home/airflow/.local/lib/python3.8/site-packages/google/api_core/grpc_helpers.py", line 75, in error_remapped_callable
    return callable_(*args, **kwargs)
  File "/home/airflow/.local/lib/python3.8/site-packages/grpc/_channel.py", line 1161, in __call__
    return _end_unary_response_blocking(state, call, False, None)
  File "/home/airflow/.local/lib/python3.8/site-packages/grpc/_channel.py", line 1004, in _end_unary_response_blocking
    raise _InactiveRpcError(state)  # pytype: disable=not-instantiable
grpc._channel._InactiveRpcError: <_InactiveRpcError of RPC that terminated with:
	status = StatusCode.NOT_FOUND
	details = "Not found: Cluster projects/oceanic-hangout-406022/regions/us-central1/clusters/shelter-cluster"
	debug_error_string = "UNKNOWN:Error received from peer ipv4:172.217.160.170:443 {created_time:"2023-12-20T14:34:01.942159701+00:00", grpc_status:5, grpc_message:"Not found: Cluster projects/oceanic-hangout-406022/regions/us-central1/clusters/shelter-cluster"}"
>

The above exception was the direct cause of the following exception:

Traceback (most recent call last):
  File "/home/airflow/.local/lib/python3.8/site-packages/airflow/providers/google/cloud/operators/dataproc.py", line 2125, in execute
    job_object = self.hook.submit_job(
  File "/home/airflow/.local/lib/python3.8/site-packages/airflow/providers/google/common/hooks/base_google.py", line 475, in inner_wrapper
    return func(self, *args, **kwargs)
  File "/home/airflow/.local/lib/python3.8/site-packages/airflow/providers/google/cloud/hooks/dataproc.py", line 790, in submit_job
    return client.submit_job(
  File "/home/airflow/.local/lib/python3.8/site-packages/google/cloud/dataproc_v1/services/job_controller/client.py", line 547, in submit_job
    response = rpc(
  File "/home/airflow/.local/lib/python3.8/site-packages/google/api_core/gapic_v1/method.py", line 131, in __call__
    return wrapped_func(*args, **kwargs)
  File "/home/airflow/.local/lib/python3.8/site-packages/google/api_core/retry.py", line 366, in retry_wrapped_func
    return retry_target(
  File "/home/airflow/.local/lib/python3.8/site-packages/google/api_core/retry.py", line 204, in retry_target
    return target()
  File "/home/airflow/.local/lib/python3.8/site-packages/google/api_core/grpc_helpers.py", line 77, in error_remapped_callable
    raise exceptions.from_grpc_error(exc) from exc
google.api_core.exceptions.NotFound: 404 Not found: Cluster projects/oceanic-hangout-406022/regions/us-central1/clusters/shelter-cluster
[2023-12-20T14:34:02.033+0000] {taskinstance.py:1400} INFO - Marking task as FAILED. dag_id=crimes_dag, task_id=submit_pyspark_job, execution_date=20231203T000000, start_date=20231220T143359, end_date=20231220T143402
[2023-12-20T14:34:02.088+0000] {standard_task_runner.py:104} ERROR - Failed to execute job 8 for task submit_pyspark_job (404 Not found: Cluster projects/oceanic-hangout-406022/regions/us-central1/clusters/shelter-cluster; 2550)
[2023-12-20T14:34:02.149+0000] {local_task_job_runner.py:228} INFO - Task exited with return code 1
[2023-12-20T14:34:02.200+0000] {taskinstance.py:2778} INFO - 0 downstream tasks scheduled from follow-on schedule check
